# 예외처리 (exception handling)

## 프로그램 오류

오류 발생시점에 따라 `컴파일 에러` 와 `런타임 에러` 를 나눌 수 있다.

이 외에도 `논리적 에러` 가 있는데, 컴파일도 잘되고 실행도 잘되지만 의도한 것과 다르게 동작하는 것을 말한다.

`컴파일 에러` : 컴파일 시에 발생하는 에러

`런타임 에러` : 실행 시에 발생하는 에러

`논리적 에러` : 실행은 되지만, 의도와 다르게 동작하는 것

- 예외클래스 계층도

![images_bluesky7017_post_60ded367-778e-4102-b583-5d9ec17f4919_image](https://user-images.githubusercontent.com/68279162/172474364-c18f7845-2be2-47a0-9a13-5d3415d650f9.png)


<aside>
💡 모든 예외의 최고 조상은 Exception 클래스

</aside>

<aside>
💡 Exception과 Error 클래스 역시 Object 클래스의 자손들

</aside>

예외 클래스는 두 그룹으로 나뉜다.

1. Exception클래스와 그 자손들

  →  FileNotFoundException, ClassNotFoundException…

1. RuntimeException클래스와 그 자손들

  → ArrayIndexOutOfBoundsException, NullPointerException…

<aside>
💡 Exception클래스들 : 사용자의 실수와 같은 외적인 요인에 의해 발생하는 예외

</aside>

<aside>
💡 RuntimeException클래스들 : 프로그래머의 실수로 발생하는 예외

</aside>

## 예외처리 :  try-catch 문

프로그램 실행도중에 발생하는 에러는 어쩔 수 없다. `하지만` 예외는 프로그래머가 이에 대한 처리를 해주어야 한다.

예외처리란?

- 프로그램 실행 시 발생할 수 있는 예기치 못한 예외의 발생에 대비한 코드를 작성하는 것.
- 목적
    - 예외의 발생으로 인해서 프로그램 종료되는 것을 막기 위해
    - 정상적인 실행 상태를 유지하기 위해

<aside>
💡 예외를 처리하지 못한다면?

</aside>

- 프로그램은 비정상 종료
- 처리되지 못한 예외는 JVM의 `예외처리기` 가 받아서 예외의 원인 화면에 출력

예외처리 - try/catch

```java
try {
	// 예외 발생 가능성이 있는 문장들을 넣는다.
} catch (Exception e) {
	// Exception이 발생했을 경우, 이를 처리하기 위한 문장을 넣는다.
} catch (Exception2 e2) {
	// Exception2가 발생했을 경우,,,
}
```

- 설명
    - 하나의 `try 블럭` 에는 여러 종류의 예외를 처리할 수 있는 `catch블럭`이 올 수 있다.
    - `발생하는 예외`와 일치하는 `catch블럭`이 없으면 예외는 처리되지 않는다.
    - try블럭 또는 catch블럭 안에 또 다른 try-catch문이 포함될 수 있다.
        - catch블럭 내의 코드에서도 예외가 발생할 수 있기 때문

예) 숫자를 0으로 나누었을 시 예외 처리

```java
public class ExceptionTest {
    public static void main(String[] args) {
        int baseNumber = 20;
        int inputNumber = 0;
        int result = 0;

        try {
            result = baseNumber / inputNumber; // 0으로 나누었기 때문에 예외 발생!
            System.out.println(result);
        }catch(ArithmeticException ae){
            System.out.println("ae = " + ae); // 이것이 출력된다.
        }
    }
}
```

## try-catch문에서의 흐름

<aside>
💡 try블럭 내에서 예외가 발생한 경우

</aside>

1. 발생한 예외와 일치하는 catch블럭이 있는지 확인
2. 일치하는 catch블럭을 찾으면, 그 catch블럭 내의 문장들을 수행
3. 그 다음 전체 try-catch문을 빠져나가서 그 다음 문장을 계속해서 수행한다.
4. 만일 일치하는 catch블럭이 없다면 예외처리는 되지 않는다.

<aside>
💡 try블럭 내에서 예외가 발생하지 않는 경우

</aside>

1. catch블럭을 거치지 않고 전체 try-catch문을 빠져나가 그 다음 문장을 계속해서 수행한다.

→ 이렇게 두 가지 경우를 봤을때 중요한 것이 있다.

- try블럭에서 예외가 발생하면, `예외가 발생한 위치 이후에 있는 try블럭의 문장들은 수행되지 않기 때문에`, try블럭에 포함시킬 코드의 범위를 잘 선택해야한다.

## 예외의 발생과 catch블럭

catch블럭은 `()` 와 `{}` 로 이루어져 있다.

`()` : 처리하고자 하는 예외타입의 참조변수 하나를 선언해야 함.

`{}` : 예외 발생 시 처리할 문장

예외처리시 catch블럭 찾는 과정

- 첫 번째 catch블럭부터 차례로 내려가면서 catch블럭의 괄호내에 선언된 참조 변수의 종류와 생성된 예외 클래스의 인스턴스에 `instanceof` 연산자를 이용해 검사
- 검사결과가 true가 나올때 까지 계속해서 찾는다.

<aside>
💡 모든 클래스는 Exception의 자손이므로, catch블럭 ()안에 Exception클래스 타입의 참조변수를 선언한다면 어떤 종류의 예외가 발생하더라도 이 catch블럭에서 처리된다.

</aside>

```java
public class ExceptionTest {
    public static void main(String[] args) {
        int baseNumber = 20;
        int inputNumber = 0;
        int result = 0;

        try {
            result = baseNumber / inputNumber;
            System.out.println(result);
        }catch(Exception e){ // 모든 예외의 조상 Exception클래스
            System.out.println("모든 예외는 여기에서 처리된다.");
        }
    }
}
```

## printStackTrace()와 getMessage()

<aside>
💡 예외가 발생했을 때 생성되는 예외 클래스에는 발생한 예외에 대한 정보가 담긴다.

</aside>

- `printStackTrace()` : 예외발생 당시의 호출스택에 있었던 메서드의 정보와 예외 메시지를 화면에 출력
- `getMessage()` : 발생한 예외클래스의 인스턴스에 저장된 메시지를 얻을 수 있음

```java
public class ExceptionTest {
    public static void main(String[] args) {
        int baseNumber = 20;
        int inputNumber = 0;
        int result = 0;

        try {
            result = baseNumber / inputNumber;
            System.out.println(result);
        }catch(ArithmeticException e){
            e.printStackTrace(); // (1)
            System.out.println(e.getMessage()); // (2)
        }
    }
}
/**
java.lang.ArithmeticException: / by zero
	at dev.hardy.ch08.ExceptionTest.main(ExceptionTest.java:10) -> printStackTrace()
/ by zero  -> getMessage()
*/
```

→ `printStackTrace()` 와 `getMessage()` 와 같은 메서드를 통해서 예외의 발생원인을 알 수 있다.

## 멀티 catch블럭

<aside>
💡 JDK 1.7 부터 ‘|’ 기호를 이용해서, 하나의 catch블럭으로 합칠 수 있게 되었고 이것을 멀티 catch블럭이라 부른다.

</aside>

- 주의할 점
    - 멀티 catch블럭에서 `|` 기호로 연결된 예외클래스들이 `조상과 자손 관계에 있다면 컴파일 에러 발생!`
        - 이유는 조상과 자손 관계이면 그냥 조상 클래스만 써주는 것과 동일하기 때문!
    - 멀티 catch블럭은 하나의 catch블럭으로 여러 예외를 처리하기 때문에, 예외발생 시에 어떤 예외가 발생 한 것인지 알 수 없다. 그래서 참조변수로는 `|` 기호로 연결된 예외 클래스들의 공통 분모인 조상 예외 클래스에 선언된 멤버만 사용할 수 있다.
    - 멀티 catch블럭에 선언된 참조변수는 상수이므로 값 변경 불가능

```java
try {
   result = baseNumber / inputNumber;
   System.out.println(result);
}catch(ArithmeticException | ArrayIndexOutOfBoundsException e){
						....
}
```

## 예외 발생시키기

키워드 `throw` 를 사용하여 예외를 발생시킬 수 있다.

1. 연산자 new를 이용해서 발생시키려는 예외 클래스를 생성
2. 키워드 throw를 이용해서 예외를 발생시킨다.

예) 예외 발생시키기

```java
public class ThrowExceptionTest {
    public static void main(String[] args) {
        try {
            Exception exception = new Exception("예외 발생시키기");
            throw exception; // 예외 고의 발생
        }catch (Exception e){
            System.out.println("에러 메세지 = " + e.getMessage());
        }
    }
}

/**
에러 메세지 = 예외 발생시키기
*/
```

(1) Exception클래스들 (Exception클래스와 그 자손)
![Untitled](https://user-images.githubusercontent.com/68279162/172474477-19e6402c-38f8-4cf1-8c9d-45d06f04263d.png)  

<aside>
💡 Exception클래스 예외 발생 시 예외 처리를 해주지 않으면 컴파일 에러가 난다.
</aside>  

(2) RuntimeException클래스들 (RuntimeException클래스와 그 자손)
![Untitled 1](https://user-images.githubusercontent.com/68279162/172474492-ff7adf4f-f647-4f19-849c-c31d81172917.png)

<aside>
💡 RuntimeException클래스 예외 발생 시 성공적으로 컴파일이 된다.

</aside>

🧐 이유가 무엇일까?

`RuntimeException클래스` 들은 프로그래머에 의해 실수로 발생하는 것들이기 때문에 예외처리를 강제하지 않는 것이다.

이때 `RuntimeException클래스들` 은 `unchecked예외` 

`Exception클래스들` 은 `checked예외`  라고 부른다.

## 메서드에 예외 선언하기

메서드의 선언부에 키워드 `throws` 를 사용해서 메서드 내에서 발생할 수 있는 예외를 적어주면됨.

여러개라면? → 쉼표(,)로 구분한다.

```java
void method() throw Exception1, Exception2,... {
	...
}
```

메서드 선언부에 예외를 선언함으로써

- 메서드를 사용하려는 사람이 메서드를 사용하기 위해서 어떤 예외들을 처리해야 하는지 알 수 있음
- 메서드에 예외를 선언할 때 일반적으로 RuntimeException 클래스들은 적지 않는다.
- 이것은 예외를 처리하는 것이 아니라, `자신을 호출한 메서드에게 예외를 전달하여 예외처리를 떠맡기는 것!`
    - 예외를 전달받은 메서드가 또다시 자신을 호출한 메서드에게 예외 전달 가능
    - 계속 `호출스택`에 있는 메서들을 따라 전달되다가 마지막에 있는 `main메서드`에서도 예외가 처리되지 않는다면 프로그램은 `전체가 종료` 된다.

## finally블럭

try-catch문과 함께 예외의 발생여부에 상관없이 실행되어야할 코드를 포함시킬 목적으로 사용

`try-catch-finally`의 순서로 구성

```java
try {
	// 예외가 발생할 가능성이 있는 문장들을 넣음
} catch (Exception e) {
  // 예외처리를 위한 문장을 적는다.
} finally {
	// 예외의 발생여부에 관계없이 항상 수행되어야하는 문장들을 넣는다.
}
```

- 예외가 발생한 경우
    - `try - catch - finally`
- 예외가 발생하지 않은 경우
    - `try - finally`

예) CustomException 생성

```java
public class CustomException extends RuntimeException{
    public CustomException() {
        super();
    }

    public CustomException(String message) {
        super(message);
    }

    public CustomException(String message, Throwable cause) {
        super(message, cause);
    }

    public CustomException(Throwable cause) {
        super(cause);
    }

    protected CustomException(String message, Throwable cause, boolean enableSuppression, boolean writableStackTrace) {
        super(message, cause, enableSuppression, writableStackTrace);
    }
}
```

예) CustomException 예외 발생 후 finally문 안에 코드 실행되는지 확인

```java
public class FinallyExceptionTest {
    public static void main(String[] args) {
        try {
            throw new CustomException("커스텀 예외 발생");
        }catch(CustomException e) {
            System.out.println(e.getMessage());
        }finally {
            System.out.println("예외 발생 여부에 관계없이 실행!");
        }
    }
}

/**
커스텀 예외 발생
예외 발생 여부에 관계없이 실행!
*/
```

## 사용자정의 예외 만들기

기존에 정의된 예외 클래스 외에 필요에 따라 새로운 예외 클래스 정의 가능

보통 Exception클래스를 상속받는 형태이지만, 필요에 따라 알맞은 예외 클래스를 선택 가능

```java
public class CustomException extends Exception{
    
    private final int ERROR_CODE; // 생성자를 통해 초기화
    
    CustomException(String message, int errorCode){ // 생성자
        super(message);
        ERROR_CODE = errorCode;
    }

    public CustomException(String message) {
        this(message, 100); // ERROR_CODE를 100으로 초기화
    }

    public int getErrorCode() {
        return ERROR_CODE;
    }
}
```

기존의 예외 클래스는 주로 `Exception`을 상속받아서 `checked예외` 로 작성하는 경우가 많았다.

요즘은 예외처리를 `선택적`으로 할 수 있도록 `RuntimeException`을 상속받아서 작성하는 쪽으로 기움

## 예외 되던지기

한 메서드에서 발생할 수 있는 예외가 여러개인 경우

- 몇 개는 try-catch문을 통해서 메서드 내에서 자체적으로 처리하고, 나머지는 선언부에 지정하여 호출한 메서드에서 처리하도록 함으로써, 양쪽에서 나눠서 처리 가능

단 하나의 예외인 경우

- 예외가 발생한 메서드와 호출한 메서드, 양쪽에서 처리하도록 할 수 있다.
- 이것은 예외를 처리한 후에 인위적으로 다시 발생시키는 방법을 통해서 가능
- 바로 `예외 되던지기` 라고 함

HOW TO?

- 예외 발생 가능한 메서드에서 try-catch문을 사용해서 예외 처리
- catch문에서 필요한 작업을 행한 후 throw문을 사용해 예외를 다시 발생시킴
- 다시 발생한 예외는 이 메서드를 호출한 메서드에게 전달되고 호출한 메서드에서 try-catch문에서 다시 예외를 또다시 처리
- 주의 점
    - 예외가 발생할 메서드에서 try-catch문을 사용해서 예외처리를 해줌과 동시에 메서드 선언부에 발생할 예외를 throws로 지정해줘야함

예)

```java
public class ReThrowExceptionTest {
    public static void main(String[] args) {
        try{
            reThrowMethod();
        } catch (Exception e){
            System.out.println("메인 메서드에서 예외 처리");
        }
    }

    static void reThrowMethod() throws Exception {
        try {
            throw new Exception();
        } catch (Exception e) {
            System.out.println("reThrowMethod에서 예외 처리");
            throw e;
        }
    }
}

/**
reThrowMethod에서 예외 처리
메인 메서드에서 예외 처리
*/
```

<aside>
💡 반환값이 있는 메서드인 경우 catch블럭에도 return문이 있어야함.

</aside>

<aside>
💡 catch블럭에서 예외 되던지기를 해서 호출한 메서드로 예외를 전달하면, return문이 없어도 된다.

</aside>

## 연결된 예외

한 예외가 다른 예외를 발생시킬 수 있다.

만약 `예외A` 가 `예외B` 를 발생시켰다면, `A` 를 `B` 의 `원인 예외` 라고 한다.

```java
public class ChainedExceptionTest {
    public static void main(String[] args) throws ResultException {
        try{
            throw new CauseException("나는 원인");
        } catch (CauseException ce){
            ResultException re = new ResultException("나는 결과"); // (1)
            re.initCause(ce); // (2)
            throw re; // (3)
        }
    }
}

class CauseException extends Exception{
    public CauseException(String message) {
        super(message);
    }
}

class ResultException extends Exception{
    public ResultException(String message) {
        super(message);
    }
}
```

(1) 예외 생성

(2) ResultException의 원인 예외로 CauseException 등록

(3) 예외 발생

`initCause()` 는 Exception클래스의 조상인 `Throwable클래스` 에 정의되어 있어 모든 예외에서 사용 가능

```java
Throwable initCause(Throwable cause) : 지정한 예외를 원인 예외로 등록
Throable getCause() : 원인 예외를 반환
```

<aside>
💡 발생한 예외를 그냥 처리하면 될 텐데, 원인 예외로 등록해서 다시 예외를 발생시킬까?

</aside>

→ 그 이유는 여러가지 예외를 하나의 큰 분류의 예외로 묶어서 다루기 위해서이다.

→ 또 다른 이유는 checked예외를 unchecked예외로 바꿀 수 있게 하기 위해

- checked예외가 발생해도 예외를 처리할 수 없는 상황이 발생하기 시작했다. 이럴 때 할 수 있는 일은 그저 의미 없는 try-catch문을 추가하는 것인데, checked예외를 unchecked예외로 바꾸면 예외처리가 선택적이 되므로 억지로 예외처리 안해도 된다.

```java
throw new RuntimeException(new CauseException("난 checked예외"));
```

→ 이렇게 Exception클래스를 상속받아 checked예외로 만든 사용자 정의 예외 클래스인 CauseException을 unchecked예외인 RuntimeException으로 감쌌기 때문에 unchecked예외가 되었다.

```java
RuntimeException(Throwable cause) // 원인 예외를 등록하는 생성자
```

Reference : 
 [자바의 정석](http://www.yes24.com/Product/Goods/24259565)